<?xml version="1.0"?>
<robot xmlns:xacro="http://www.ros.org/wiki/xacro">

    <xacro:macro name="camera" params="base_link">

        <joint name="camera_joint" type="revolute">
            <parent link="${base_link}" />
            <child link="camera_link" />
            <origin xyz="0 0 0.1" rpy="0 0 0" />
            <axis xyz="0 0 1" />
            <limit lower="-3.14" upper="3.14" effort="50" velocity="10" />
        </joint>

        <link name="camera_link">
            <visual>
                <geometry>
                    <box size="0.010 0.03 0.03" />
                </geometry>
                <material name="red" />
            </visual>
            <inertial>
                <origin xyz="0 0 0" rpy="0 0 0" />
                <mass value="0.5" />
                <inertia
                    ixx="1.05" ixy="0.00" ixz="0.00"
                    iyx="0.00" iyy="1.05" iyz="0.00"
                    izx="0.00" izy="0.00" izz="1.05"
                />
            </inertial>
        </link>


        <joint name="camera_optical_joint" type="fixed">
            <parent link="camera_link" />
            <child link="camera_link_optical" />
            <origin xyz="0 0 0" rpy="${-pi/2} 0 ${-pi/2}" />
        </joint>

        <link name="camera_link_optical">
        </link>


        <gazebo reference="camera_link">
            <material>Gazebo/Red</material>

            <sensor name="camera" type="camera">
                <pose> 0 0 0 0 0 0 </pose>
                <visualize>true</visualize>
                <update_rate>10</update_rate>
                <camera>
                    <horizontal_fov>1.089</horizontal_fov>
                    <image>
                        <format>R8G8B8</format>
                        <width>640</width>
                        <height>480</height>
                    </image>
                    <clip>
                        <near>0.05</near>
                        <far>8.0</far>
                    </clip>
                </camera>
                <plugin name="camera_controller" filename="libgazebo_ros_camera.so">
                    <frame_name>camera_link_optical</frame_name>
                </plugin>
            </sensor>
        </gazebo>

        <!-- Transmission -->
        <transmission name="camera_tran">
            <type>transmission_interface/SimpleTransmission</type>
            <joint name="camera_joint">
                <hardwareInterface>hardware_interface/EffortJointInterface</hardwareInterface>
            </joint>
            <actuator name="camera_joint_motor">
                <hardwareInterface>hardware_interface/EffortJointInterface</hardwareInterface>
                <mechanicalReduction>1</mechanicalReduction>
            </actuator>
        </transmission>

    </xacro:macro>
</robot>